Workbook

Sheet README
A1: Production Process & OEE Optimization - Excel + Power BI
A2: Pharma manufacturing (solid dosage) | Jan-Jun 2026 | 4 production lines | 12 products
A4: Purpose
A5: Measure how effectively production lines are used (OEE), find where capacity is being lost, and prioritise process-improvement actions.
A6: Excel = data model, calculations, Pareto / bottleneck analysis, improvement scenario. Power BI = interactive KPI dashboard connected to this workbook.
A8: DATA DISCLOSURE
A9: All data is SIMULATED for portfolio / learning purposes. It is not from any real plant or company.
A10: Patterns (e.g. recurring Tablet Press 2 failures in April, a packaging-material shortage on Line 4 in May, weaker night shift) were built into the simulation so the analysis has something realistic to find.
A11: Describe it as 'simulated plant data' on a CV or in an interview.
A13: OEE definitions used
A14: Planned Production Time = Shift time - Planned downtime (handover, meals, planned PM).
A15: Operating Time = Planned Production Time - Unplanned downtime (breakdown, changeover, material shortage, QA hold, minor stoppage, utility failure).
... A40: Get Data > Excel > select Production_Log, Downtime_Log, Quality_Log, Line_Master, Machine_Master, Rate_Master. See the separate Power BI build guide for relationships and DAX.

Sheet Summary
A1: Production Process & OEE Optimization - Summary
A2: Simulated pharma plant data, Jan-Jun 2026 (4 lines, 12 products). All figures are live formulas.
A4: Headline KPIs (plant)
A5: OEE | B5: Availability | C5: Performance | D5: Quality | E5: Gap vs 85% benchmark | F5: Unplanned downtime (h) | G5: Capacity utilization | H5: Production runs analysed
A6: =OEE_Analysis!J9 -> 0.71203445 | B6: =OEE_Analysis!G9 -> 0.84755103 | C6: =OEE_Analysis!H9 -> 0.85899666 | D6: =OEE_Analysis!I9 -> 0.97801086 | E6: =OEE_Analysis!K9 -> -0.13796555 | F6: =OEE_Analysis!F9 -> 1878.4 | G6: =OEE_Analysis!M9 -> 0.67427751 | H6: =OEE_Analysis!C9 -> 1663
A8: Key findings (auto-generated from the analysis sheets)
A9: ="1. Lowest OEE line: "&INDEX(OEE_Analysis!$B$5:$B$8,MATCH(MIN(OEE_Analysis!$J$5:$J$8),OEE_Analysis!$J$5:$J$8,0))&" at "&TEXT(MIN(OEE_Analysis!$J$5:$J$8),"0.0%")&" vs plant "&TEXT(OEE_Analysis!$J$9,"0.0%")&" and a "&TEXT(Assumptions!$B$7,"0%")&" benchmark." -> 1. Lowest OEE line: Line 2 - Compression & Coating at 64.1% vs plant 71.2% and a 85% benchmark.
A10: ="2. Biggest availability loss: "&Downtime_Analysis!B15&" ("&TEXT(Downtime_Analysis!D15,"0%")&" of downtime); top two reasons ("&Downtime_Analysis!B15&" + "&Downtime_Analysis!B16&") = "&TEXT(Downtime_Analysis!E16,"0%")&"." -> 2. Biggest availability loss: Breakdown (35% of downtime); top two reasons (Breakdown + Minor Stoppage) = 65%.
A11: ="3. Bottleneck machine: "&Downtime_Analysis!B52&" ("&Downtime_Analysis!C52&") lost "&TEXT(Downtime_Analysis!D52,"#,##0")&" h, i.e. "&TEXT(Downtime_Analysis!F52,"0%")&" of all plant downtime." -> 3. Bottleneck machine: Tablet Press 2 (L2) lost 493 h, i.e. 26% of all plant downtime.
A12: ="4. Weakest shift: Shift "&INDEX(OEE_Analysis!$A$24:$A$26,MATCH(MIN(OEE_Analysis!$E$24:$E$26),OEE_Analysis!$E$24:$E$26,0))&" at "&TEXT(MIN(OEE_Analysis!$E$24:$E$26),"0.0%")&" OEE vs best shift "&TEXT(MAX(OEE_Analysis!$E$24:$E$26),"0.0%")&"." -> 4. Weakest shift: Shift C at 65.9% OEE vs best shift 73.9%.
A13: ="5. Worst month for the plant: "&TEXT(INDEX(OEE_Analysis!$A$31:$A$36,MATCH(MIN(OEE_Analysis!$F$31:$F$36),OEE_Analysis!$F$31:$F$36,0)),"mmm yyyy")&" ("&TEXT(MIN(OEE_Analysis!$F$31:$F$36),"0.0%")&" OEE)." -> 5. Worst month for the plant: Apr 2026 (68.4% OEE).
A14: ="6. Top quality loss: "&Quality_Analysis!B25&" ("&Quality_Analysis!C25&") - "&TEXT(Quality_Analysis!E25,"0%")&" of production time lost to rejects." -> 6. Top quality loss: Coating defect (Compression & Coating) - 15% of production time lost to rejects.
A15: ="7. Scenario upside: the improvement levers on the Scenario sheet lift plant OEE by "&TEXT(Scenario!O15*100,"0.0")&" percentage points to "&TEXT(Scenario!N15,"0.0%")&" (potential, not realised)." -> 7. Scenario upside: the improvement levers on the Scenario sheet lift plant OEE by 2.4 percentage points to 73.6% (potential, not realised).
A18: Charts

Sheet OEE_Analysis
A1: OEE Analysis
A2: OEE = Availability x Performance x Quality | all aggregations are time-weighted (unit-agnostic across tablets / capsules / strips)
A3: 1. Line-level OEE summary
A4: Line | B4: Line Name | C4: Runs | D4: Planned Prod. Time (h) | E4: Operating Time (h) | F4: Unplanned Downtime (h) | G4: Availability | H4: Performance | I4: Quality | J4: OEE | K4: Gap vs World-class (pts) | L4: Plan Achievement | M4: Capacity Utilization | N4: Schedule Loading | O4: Rejection % (units) | P4: Energy kWh / 1,000 good units | Q4: Water kL / 1,000 good units
A5: L1 | B5: =INDEX(Line_Master!$B$2:$B$5,MATCH(A5,Line_Master!$A$2:$A$5,0)) -> Line 1 - Compression & Coating | C5: =COUNTIFS(Production_Log!$E$2:$E$5000,$A5) -> 456 | D5: =SUMIFS(Production_Log!$J$2:$J$5000,Production_Log!$E$2:$E$5000,$A5)/60 -> 3378.25 | E5: =SUMIFS(Production_Log!$L$2:$L$5000,Production_Log!$E$2:$E$5000,$A5)/60 -> 2908.4333 | F5: =SUMIFS(Production_Log!$K$2:$K$5000,Production_Log!$E$2:$E$5000,$A5)/60 -> 469.81667 | G5: =IF(D5=0,0,E5/D5) -> 0.86092898 | H5: =IF(E5=0,0,SUMIFS(Production_Log!$R$2:$R$5000,Production_Log!$E$2:$E$5000,$A5)/60/E5) -> 0.8815771 | I5: =IF(SUMIFS(Production_Log!$R$2:$R$5000,Production_Log!$E$2:$E$5000,$A5)=0,0,SUMIFS(Production_Log!$S$2:$S$5000,Production_Log!$E$2:$E$5000,$A5)/SUMIFS(Production_Log!$R$2:$R$5000,Production_Log!$E$2:$E$5000,$A5)) -> 0.98106271 | J5: =G5*H5*I5 -> 0.74460234 | K5: =J5-Assumptions!$B$7 -> -0.10539766 | L5: =IF(SUMIFS(Production_Log!$Q$2:$Q$5000,Production_Log!$E$2:$E$5000,$A5)=0,0,SUMIFS(Production_Log!$P$2:$P$5000,Production_Log!$E$2:$E$5000,$A5)/SUMIFS(Production_Log!$Q$2:$Q$5000,Production_Log!$E$2:$E$5000,$A5)) -> 0.95746867 | M5: =SUMIFS(Production_Log!$R$2:$R$5000,Production_Log!$E$2:$E$5000,$A5)/SUMIFS(Production_Log!$H$2:$H$5000,Production_Log!$E$2:$E$5000,$A5) -> 0.70285313 | N5: =SUMIFS(Production_Log!$H$2:$H$5000,Production_Log!$E$2:$E$5000,$A5)/(Assumptions!$B$8*Assumptions!$B$5*Assumptions!$B$4) -> 1 | O5: =SUMIFS(Production_Log!$O$2:$O$5000,Production_Log!$E$2:$E$5000,$A5)/SUMIFS(Production_Log!$N$2:$N$5000,Production_Log!$E$2:$E$5000,$A5) -> 0.018679986 | P5: =SUMIFS(Production_Log!$X$2:$X$5000,Production_Log!$E$2:$E$5000,$A5)/SUMIFS(Production_Log!$P$2:$P$5000,Production_Log!$E$2:$E$5000,$A5)*1000 -> 1.1300018 | Q5: =SUMIFS(Production_Log!$Y$2:$Y$5000,Production_Log!$E$2:$E$5000,$A5)/SUMIFS(Production_Log!$P$2:$P$5000,Production_Log!$E$2:$E$5000,$A5)*1000 -> 0.0059484539
A6: L2 | B6: =INDEX(Line_Master!$B$2:$B$5,MATCH(A6,Line_Master!$A$2:$A$5,0)) -> Line 2 - Compression & Coating | C6: =COUNTIFS(Production_Log!$E$2:$E$5000,$A6) -> 447 | D6: =SUMIFS(Production_Log!$J$2:$J$5000,Production_Log!$E$2:$E$5000,$A6)/60 -> 3313.25 | E6: =SUMIFS(Production_Log!$L$2:$L$5000,Production_Log!$E$2:$E$5000,$A6)/60 -> 2586.5 | F6: =SUMIFS(Production_Log!$K$2:$K$5000,Production_Log!$E$2:$E$5000,$A6)/60 -> 726.75 | G6: =IF(D6=0,0,E6/D6) -> 0.78065344 | H6: =IF(E6=0,0,SUMIFS(Production_Log!$R$2:$R$5000,Production_Log!$E$2:$E$5000,$A6)/60/E6) -> 0.84539478 | I6: =IF(SUMIFS(Production_Log!$R$2:$R$5000,Production_Log!$E$2:$E$5000,$A6)=0,0,SUMIFS(Production_Log!$S$2:$S$5000,Production_Log!$E$2:$E$5000,$A6)/SUMIFS(Production_Log!$R$2:$R$5000,Production_Log!$E$2:$E$5000,$A6)) -> 0.97134903 | J6: =G6*H6*I6 -> 0.64105184 | K6: =J6-Assumptions!$B$7 -> -0.20894816 | L6: =IF(SUMIFS(Production_Log!$Q$2:$Q$5000,Production_Log!$E$2:$E$5000,$A6)=0,0,SUMIFS(Production_Log!$P$2:$P$5000,Production_Log!$E$2:$E$5000,$A6)/SUMIFS(Production_Log!$Q$2:$Q$5000,Production_Log!$E$2:$E$5000,$A6)) -> 0.82227308 | M6: =SUMIFS(Production_Log!$R$2:$R$5000,Production_Log!$E$2:$E$5000,$A6)/SUMIFS(Production_Log!$H$2:$H$5000,Production_Log!$E$2:$E$5000,$A6) -> 0.61146913 | N6: =SUMIFS(Production_Log!$H$2:$H$5000,Production_Log!$E$2:$E$5000,$A6)/(Assumptions!$B$8*Assumptions!$B$5*Assumptions!$B$4) -> 0.98026316 | O6: =SUMIFS(Production_Log!$O$2:$O$5000,Production_Log!$E$2:$E$5000,$A6)/SUMIFS(Production_Log!$N$2:$N$5000,Production_Log!$E$2:$E$5000,$A6) -> 0.027957459 | P6: =SUMIFS(Production_Log!$X$2:$X$5000,Production_Log!$E$2:$E$5000,$A6)/SUMIFS(Production_Log!$P$2:$P$5000,Production_Log!$E$2:$E$5000,$A6)*1000 -> 1.6181014 | Q6: =SUMIFS(Production_Log!$Y$2:$Y$5000,Production_Log!$E$2:$E$5000,$A6)/SUMIFS(Production_Log!$P$2:$P$5000,Production_Log!$E$2:$E$5000,$A6)*1000 -> 0.0086787966
A7: L3 | B7: =INDEX(Line_Master!$B$2:$B$5,MATCH(A7,Line_Master!$A$2:$A$5,0)) -> Line 3 - Capsule Filling | C7: =COUNTIFS(Production_Log!$E$2:$E$5000,$A7) -> 304 | D7: =SUMIFS(Production_Log!$J$2:$J$5000,Production_Log!$E$2:$E$5000,$A7)/60 -> 2248 | E7: =SUMIFS(Production_Log!$L$2:$L$5000,Production_Log!$E$2:$E$5000,$A7)/60 -> 2040.95 | F7: =SUMIFS(Production_Log!$K$2:$K$5000,Production_Log!$E$2:$E$5000,$A7)/60 -> 207.05 | G7: =IF(D7=0,0,E7/D7) -> 0.90789591 | H7: =IF(E7=0,0,SUMIFS(Production_Log!$R$2:$R$5000,Production_Log!$E$2:$E$5000,$A7)/60/E7) -> 0.90614108 | I7: =IF(SUMIFS(Production_Log!$R$2:$R$5000,Production_Log!$E$2:$E$5000,$A7)=0,0,SUMIFS(Production_Log!$S$2:$S$5000,Production_Log!$E$2:$E$5000,$A7)/SUMIFS(Production_Log!$R$2:$R$5000,Production_Log!$E$2:$E$5000,$A7)) -> 0.98255773 | J7: =G7*H7*I7 -> 0.80833234 | K7: =J7-Assumptions!$B$7 -> -0.041667664 | L7: =IF(SUMIFS(Production_Log!$Q$2:$Q$5000,Production_Log!$E$2:$E$5000,$A7)=0,0,SUMIFS(Production_Log!$P$2:$P$5000,Production_Log!$E$2:$E$5000,$A7)/SUMIFS(Production_Log!$Q$2:$Q$5000,Production_Log!$E$2:$E$5000,$A7)) -> 1.0380223 | M7: =SUMIFS(Production_Log!$R$2:$R$5000,Production_Log!$E$2:$E$5000,$A7)/SUMIFS(Production_Log!$H$2:$H$5000,Production_Log!$E$2:$E$5000,$A7) -> 0.76043941 | N7: =SUMIFS(Production_Log!$H$2:$H$5000,Production_Log!$E$2:$E$5000,$A7)/(Assumptions!$B$8*Assumptions!$B$5*Assumptions!$B$4) -> 0.66666667 | O7: =SUMIFS(Production_Log!$O$2:$O$5000,Production_Log!$E$2:$E$5000,$A7)/SUMIFS(Production_Log!$N$2:$N$5000,Production_Log!$E$2:$E$5000,$A7) -> 0.01712905 | P7: =SUMIFS(Production_Log!$X$2:$X$5000,Production_Log!$E$2:$E$5000,$A7)/SUMIFS(Production_Log!$P$2:$P$5000,Production_Log!$E$2:$E$5000,$A7)*1000 -> 1.1466806 | Q7: =SUMIFS(Production_Log!$Y$2:$Y$5000,Production_Log!$E$2:$E$5000,$A7)/SUMIFS(Production_Log!$P$2:$P$5000,Production_Log!$E$2:$E$5000,$A7)*1000 -> 0.0048433731
A8: L4 | B8: =INDEX(Line_Master!$B$2:$B$5,MATCH(A8,Line_Master!$A$2:$A$5,0)) -> Line 4 - Blister Packing | C8: =COUNTIFS(Production_Log!$E$2:$E$5000,$A8) -> 456 | D8: =SUMIFS(Production_Log!$J$2:$J$5000,Production_Log!$E$2:$E$5000,$A8)/60 -> 3382 | E8: =SUMIFS(Production_Log!$L$2:$L$5000,Production_Log!$E$2:$E$5000,$A8)/60 -> 2907.2167 | F8: =SUMIFS(Production_Log!$K$2:$K$5000,Production_Log!$E$2:$E$5000,$A8)/60 -> 474.78333 | G8: =IF(D8=0,0,E8/D8) -> 0.85961463 | H8: =IF(E8=0,0,SUMIFS(Production_Log!$R$2:$R$5000,Production_Log!$E$2:$E$5000,$A8)/60/E8) -> 0.81541138 | I8: =IF(SUMIFS(Production_Log!$R$2:$R$5000,Production_Log!$E$2:$E$5000,$A8)=0,0,SUMIFS(Production_Log!$S$2:$S$5000,Production_Log!$E$2:$E$5000,$A8)/SUMIFS(Production_Log!$R$2:$R$5000,Production_Log!$E$2:$E$5000,$A8)) -> 0.97730763 | J8: =G8*H8*I8 -> 0.68503357 | K8: =J8-Assumptions!$B$7 -> -0.16496643 | L8: =IF(SUMIFS(Production_Log!$Q$2:$Q$5000,Production_Log!$E$2:$E$5000,$A8)=0,0,SUMIFS(Production_Log!$P$2:$P$5000,Production_Log!$E$2:$E$5000,$A8)/SUMIFS(Production_Log!$Q$2:$Q$5000,Production_Log!$E$2:$E$5000,$A8)) -> 0.87878485 | M8: =SUMIFS(Production_Log!$R$2:$R$5000,Production_Log!$E$2:$E$5000,$A8)/SUMIFS(Production_Log!$H$2:$H$5000,Production_Log!$E$2:$E$5000,$A8) -> 0.64982937 | N8: =SUMIFS(Production_Log!$H$2:$H$5000,Production_Log!$E$2:$E$5000,$A8)/(Assumptions!$B$8*Assumptions!$B$5*Assumptions!$B$4) -> 1 | O8: =SUMIFS(Production_Log!$O$2:$O$5000,Production_Log!$E$2:$E$5000,$A8)/SUMIFS(Production_Log!$N$2:$N$5000,Production_Log!$E$2:$E$5000,$A8) -> 0.02263 | P8: =SUMIFS(Production_Log!$X$2:$X$5000,Production_Log!$E$2:$E$5000,$A8)/SUMIFS(Production_Log!$P$2:$P$5000,Production_Log!$E$2:$E$5000,$A8)*1000 -> 2.818792 | Q8: =SUMIFS(Production_Log!$Y$2:$Y$5000,Production_Log!$E$2:$E$5000,$A8)/SUMIFS(Production_Log!$P$2:$P$5000,Production_Log!$E$2:$E$5000,$A8)*1000 -> 0.0032128468
A9: Plant | B9: All lines | C9: =SUM(C5:C8) -> 1663 | D9: =SUM(D5:D8) -> 12321.5 | E9: =SUM(E5:E8) -> 10443.1 | F9: =SUM(F5:F8) -> 1878.4 | G9: =E9/D9 -> 0.84755103 | H9: =SUM(Production_Log!$R$2:$R$5000)/60/E9 -> 0.85899666 | I9: =SUM(Production_Log!$S$2:$S$5000)/SUM(Production_Log!$R$2:$R$5000) -> 0.97801086 | J9: =G9*H9*I9 -> 0.71203445 | K9: =J9-Assumptions!$B$7 -> -0.13796555 | L9: =J9/Assumptions!$B$6 -> 0.91286468 | M9: =SUM(Production_Log!$R$2:$R$5000)/SUM(Production_Log!$H$2:$H$5000) -> 0.67427751 | N9: =SUM(Production_Log!$H$2:$H$5000)/(Assumptions!$B$8*Assumptions!$B$5*Assumptions!$B$4*COUNTA(Line_Master!$A$2:$A$5)) -> 0.91173246 | O9: n/a (mixed units) | P9: n/a (mixed units) | Q9: n/a (mixed units)
A10: Benchmark | B10: World-class | G10: =Assumptions!B10 -> 0.9 | H10: =Assumptions!B11 -> 0.95 | I10: =Assumptions!B12 -> 0.999 | J10: =Assumptions!B7 -> 0.85
A11: Notes: Availability = Operating Time / Planned Production Time. Performance = Ideal Time / Operating Time. Quality = Fully Productive Time / Ideal Time. Plan Achievement = Good units / Target units. Capacity Utilization = Ideal Time / Shift Time. Schedule Loading = scheduled shift time / 24 h calendar time.
A13: 2. OEE by Line x Shift
A14: Line | B14: A | C14: B | D14: C | E14: All shifts
A15: L1 | B15: =IF(SUMIFS(Production_Log!$J$2:$J$5000,Production_Log!$E$2:$E$5000,$A15,Production_Log!$D$2:$D$5000,B$14)=0,"n/a",SUMIFS(Production_Log!$S$2:$S$5000,Production_Log!$E$2:$E$5000,$A15,Production_Log!$D$2:$D$5000,B$14)/SUMIFS(Production_Log!$J$2:$J$5000,Production_Log!$E$2:$E$5000,$A15,Production_Log!$D$2:$D$5000,B$14)) -> 0.76735173 | C15: =IF(SUMIFS(Production_Log!$J$2:$J$5000,Production_Log!$E$2:$E$5000,$A15,Production_Log!$D$2:$D$5000,C$14)=0,"n/a",SUMIFS(Production_Log!$S$2:$S$5000,Production_Log!$E$2:$E$5000,$A15,Production_Log!$D$2:$D$5000,C$14)/SUMIFS(Production_Log!$J$2:$J$5000,Production_Log!$E$2:$E$5000,$A15,Production_Log!$D$2:$D$5000,C$14)) -> 0.75479707 | D15: =IF(SUMIFS(Production_Log!$J$2:$J$5000,Production_Log!$E$2:$E$5000,$A15,Production_Log!$D$2:$D$5000,D$14)=0,"n/a",SUMIFS(Production_Log!$S$2:$S$5000,Production_Log!$E$2:$E$5000,$A15,Production_Log!$D$2:$D$5000,D$14)/SUMIFS(Production_Log!$J$2:$J$5000,Production_Log!$E$2:$E$5000,$A15,Production_Log!$D$2:$D$5000,D$14)) -> 0.71213248 | E15: =J5 -> 0.74460234
A16: L2 | B16: =IF(SUMIFS(Production_Log!$J$2:$J$5000,Production_Log!$E$2:$E$5000,$A16,Production_Log!$D$2:$D$5000,B$14)=0,"n/a",SUMIFS(Production_Log!$S$2:$S$5000,Production_Log!$E$2:$E$5000,$A16,Production_Log!$D$2:$D$5000,B$14)/SUMIFS(Production_Log!$J$2:$J$5000,Production_Log!$E$2:$E$5000,$A16,Production_Log!$D$2:$D$5000,B$14)) -> 0.65981303 | C16: =IF(SUMIFS(Production_Log!$J$2:$J$5000,Production_Log!$E$2:$E$5000,$A16,Production_Log!$D$2:$D$5000,C$14)=0,"n/a",SUMIFS(Production_Log!$S$2:$S$5000,Production_Log!$E$2:$E$5000,$A16,Production_Log!$D$2:$D$5000,C$14)/SUMIFS(Production_Log!$J$2:$J$5000,Production_Log!$E$2:$E$5000,$A16,Production_Log!$D$2:$D$5000,C$14)) -> 0.65550945 | D16: =IF(SUMIFS(Production_Log!$J$2:$J$5000,Production_Log!$E$2:$E$5000,$A16,Production_Log!$D$2:$D$5000,D$14)=0,"n/a",SUMIFS(Production_Log!$S$2:$S$5000,Production_Log!$E$2:$E$5000,$A16,Production_Log!$D$2:$D$5000,D$14)/SUMIFS(Production_Log!$J$2:$J$5000,Production_Log!$E$2:$E$5000,$A16,Production_Log!$D$2:$D$5000,D$14)) -> 0.60829216 | E16: =J6 -> 0.64105184
A17: L3 | B17: =IF(SUMIFS(Production_Log!$J$2:$J$5000,Production_Log!$E$2:$E$5000,$A17,Production_Log!$D$2:$D$5000,B$14)=0,"n/a",SUMIFS(Production_Log!$S$2:$S$5000,Production_Log!$E$2:$E$5000,$A17,Production_Log!$D$2:$D$5000,B$14)/SUMIFS(Production_Log!$J$2:$J$5000,Production_Log!$E$2:$E$5000,$A17,Production_Log!$D$2:$D$5000,B$14)) -> 0.81928521 | C17: =IF(SUMIFS(Production_Log!$J$2:$J$5000,Production_Log!$E$2:$E$5000,$A17,Production_Log!$D$2:$D$5000,C$14)=0,"n/a",SUMIFS(Production_Log!$S$2:$S$5000,Production_Log!$E$2:$E$5000,$A17,Production_Log!$D$2:$D$5000,C$14)/SUMIFS(Production_Log!$J$2:$J$5000,Production_Log!$E$2:$E$5000,$A17,Production_Log!$D$2:$D$5000,C$14)) -> 0.79762516 | D17: =IF(SUMIFS(Production_Log!$J$2:$J$5000,Production_Log!$E$2:$E$5000,$A17,Production_Log!$D$2:$D$5000,D$14)=0,"n/a",SUMIFS(Production_Log!$S$2:$S$5000,Production_Log!$E$2:$E$5000,$A17,Production_Log!$D$2:$D$5000,D$14)/SUMIFS(Production_Log!$J$2:$J$5000,Production_Log!$E$2:$E$5000,$A17,Production_Log!$D$2:$D$5000,D$14)) -> n/a | E17: =J7 -> 0.80833234
A18: L4 | B18: =IF(SUMIFS(Production_Log!$J$2:$J$5000,Production_Log!$E$2:$E$5000,$A18,Production_Log!$D$2:$D$5000,B$14)=0,"n/a",SUMIFS(Production_Log!$S$2:$S$5000,Production_Log!$E$2:$E$5000,$A18,Production_Log!$D$2:$D$5000,B$14)/SUMIFS(Production_Log!$J$2:$J$5000,Production_Log!$E$2:$E$5000,$A18,Production_Log!$D$2:$D$5000,B$14)) -> 0.70647675 | C18: =IF(SUMIFS(Production_Log!$J$2:$J$5000,Production_Log!$E$2:$E$5000,$A18,Production_Log!$D$2:$D$5000,C$14)=0,"n/a",SUMIFS(Production_Log!$S$2:$S$5000,Production_Log!$E$2:$E$5000,$A18,Production_Log!$D$2:$D$5000,C$14)/SUMIFS(Production_Log!$J$2:$J$5000,Production_Log!$E$2:$E$5000,$A18,Production_Log!$D$2:$D$5000,C$14)) -> 0.69425794 | D18: =IF(SUMIFS(Production_Log!$J$2:$J$5000,Production_Log!$E$2:$E$5000,$A18,Production_Log!$D$2:$D$5000,D$14)=0,"n/a",SUMIFS(Production_Log!$S$2:$S$5000,Production_Log!$E$2:$E$5000,$A18,Production_Log!$D$2:$D$5000,D$14)/SUMIFS(Production_Log!$J$2:$J$5000,Production_Log!$E$2:$E$5000,$A18,Production_Log!$D$2:$D$5000,D$14)) -> 0.65482807 | E18: =J8 -> 0.68503357
A19: Plant | B19: =SUMIFS(Production_Log!$S$2:$S$5000,Production_Log!$D$2:$D$5000,B$14)/SUMIFS(Production_Log!$J$2:$J$5000,Production_Log!$D$2:$D$5000,B$14) -> 0.73866628 | C19: =SUMIFS(Production_Log!$S$2:$S$5000,Production_Log!$D$2:$D$5000,C$14)/SUMIFS(Production_Log!$J$2:$J$5000,Production_Log!$D$2:$D$5000,C$14) -> 0.72590432 | D19: =SUMIFS(Production_Log!$S$2:$S$5000,Production_Log!$D$2:$D$5000,D$14)/SUMIFS(Production_Log!$J$2:$J$5000,Production_Log!$D$2:$D$5000,D$14) -> 0.65871211 | E19: =J9 -> 0.71203445
A22: 3. Plant performance by Shift (A / B / C)
A23: Shift | B23: Availability | C23: Performance | D23: Quality | E23: OEE | F23: Unplanned Downtime (h)
A24: A | B24: =SUMIFS(Production_Log!$L$2:$L$5000,Production_Log!$D$2:$D$5000,$A24)/SUMIFS(Production_Log!$J$2:$J$5000,Production_Log!$D$2:$D$5000,$A24) -> 0.86198724 | C24: =SUMIFS(Production_Log!$R$2:$R$5000,Production_Log!$D$2:$D$5000,$A24)/SUMIFS(Production_Log!$L$2:$L$5000,Production_Log!$D$2:$D$5000,$A24) -> 0.87587322 | D24: =SUMIFS(Production_Log!$S$2:$S$5000,Production_Log!$D$2:$D$5000,$A24)/SUMIFS(Production_Log!$R$2:$R$5000,Production_Log!$D$2:$D$5000,$A24) -> 0.9783769 | E24: =B24*C24*D24 -> 0.73866628 | F24: =SUMIFS(Production_Log!$K$2:$K$5000,Production_Log!$D$2:$D$5000,$A24)/60 -> 609.53333
A25: B | B25: =SUMIFS(Production_Log!$L$2:$L$5000,Production_Log!$D$2:$D$5000,$A25)/SUMIFS(Production_Log!$J$2:$J$5000,Production_Log!$D$2:$D$5000,$A25) -> 0.85689385 | C25: =SUMIFS(Production_Log!$R$2:$R$5000,Production_Log!$D$2:$D$5000,$A25)/SUMIFS(Production_Log!$L$2:$L$5000,Production_Log!$D$2:$D$5000,$A25) -> 0.86588992 | D25: =SUMIFS(Production_Log!$S$2:$S$5000,Production_Log!$D$2:$D$5000,$A25)/SUMIFS(Production_Log!$R$2:$R$5000,Production_Log!$D$2:$D$5000,$A25) -> 0.97833969 | E25: =B25*C25*D25 -> 0.72590432 | F25: =SUMIFS(Production_Log!$K$2:$K$5000,Production_Log!$D$2:$D$5000,$A25)/60 -> 647.23333
A26: C | B26: =SUMIFS(Production_Log!$L$2:$L$5000,Production_Log!$D$2:$D$5000,$A26)/SUMIFS(Production_Log!$J$2:$J$5000,Production_Log!$D$2:$D$5000,$A26) -> 0.81620716 | C26: =SUMIFS(Production_Log!$R$2:$R$5000,Production_Log!$D$2:$D$5000,$A26)/SUMIFS(Production_Log!$L$2:$L$5000,Production_Log!$D$2:$D$5000,$A26) -> 0.82604625 | D26: =SUMIFS(Production_Log!$S$2:$S$5000,Production_Log!$D$2:$D$5000,$A26)/SUMIFS(Production_Log!$R$2:$R$5000,Production_Log!$D$2:$D$5000,$A26) -> 0.97699173 | E26: =B26*C26*D26 -> 0.65871211 | F26: =SUMIFS(Production_Log!$K$2:$K$5000,Production_Log!$D$2:$D$5000,$A26)/60 -> 621.63333
A29: 4. Monthly OEE trend
A30: Month | B30: L1 | C30: L2 | D30: L3 | E30: L4 | F30: Plant OEE | G30: Plant Availability | H30: Plant Performance | I30: Plant Quality | J30: Unplanned Downtime (h)
A31: 46023 | B31: =SUMIFS(Production_Log!$S$2:$S$5000,Production_Log!$C$2:$C$5000,$A31,Production_Log!$E$2:$E$5000,"L1")/SUMIFS(Production_Log!$J$2:$J$5000,Production_Log!$C$2:$C$5000,$A31,Production_Log!$E$2:$E$5000,"L1") -> 0.74418159 | C31: =SUMIFS(Production_Log!$S$2:$S$5000,Production_Log!$C$2:$C$5000,$A31,Production_Log!$E$2:$E$5000,"L2")/SUMIFS(Production_Log!$J$2:$J$5000,Production_Log!$C$2:$C$5000,$A31,Production_Log!$E$2:$E$5000,"L2") -> 0.66650309 | D31: =SUMIFS(Production_Log!$S$2:$S$5000,Production_Log!$C$2:$C$5000,$A31,Production_Log!$E$2:$E$5000,"L3")/SUMIFS(Production_Log!$J$2:$J$5000,Production_Log!$C$2:$C$5000,$A31,Production_Log!$E$2:$E$5000,"L3") -> 0.81621678 | E31: =SUMIFS(Production_Log!$S$2:$S$5000,Production_Log!$C$2:$C$5000,$A31,Production_Log!$E$2:$E$5000,"L4")/SUMIFS(Production_Log!$J$2:$J$5000,Production_Log!$C$2:$C$5000,$A31,Production_Log!$E$2:$E$5000,"L4") -> 0.68500052 | F31: =SUMIFS(Production_Log!$S$2:$S$5000,Production_Log!$C$2:$C$5000,$A31)/SUMIFS(Production_Log!$J$2:$J$5000,Production_Log!$C$2:$C$5000,$A31) -> 0.71990625 | G31: =SUMIFS(Production_Log!$L$2:$L$5000,Production_Log!$C$2:$C$5000,$A31)/SUMIFS(Production_Log!$J$2:$J$5000,Production_Log!$C$2:$C$5000,$A31) -> 0.85890686 | H31: =SUMIFS(Production_Log!$R$2:$R$5000,Production_Log!$C$2:$C$5000,$A31)/SUMIFS(Production_Log!$L$2:$L$5000,Production_Log!$C$2:$C$5000,$A31) -> 0.85684113 | I31: =SUMIFS(Production_Log!$S$2:$S$5000,Production_Log!$C$2:$C$5000,$A31)/SUMIFS(Production_Log!$R$2:$R$5000,Production_Log!$C$2:$C$5000,$A31) -> 0.9782043 | J31: =SUMIFS(Production_Log!$K$2:$K$5000,Production_Log!$C$2:$C$5000,$A31)/60 -> 298.8
A32: 46054 | B32: =SUMIFS(Production_Log!$S$2:$S$5000,Production_Log!$C$2:$C$5000,$A32,Production_Log!$E$2:$E$5000,"L1")/SUMIFS(Production_Log!$J$2:$J$5000,Production_Log!$C$2:$C$5000,$A32,Production_Log!$E$2:$E$5000,"L1") -> 0.77112945 | C32: =SUMIFS(Production_Log!$S$2:$S$5000,Production_Log!$C$2:$C$5000,$A32,Production_Log!$E$2:$E$5000,"L2")/SUMIFS(Production_Log!$J$2:$J$5000,Production_Log!$C$2:$C$5000,$A32,Production_Log!$E$2:$E$5000,"L2") -> 0.65017357 | D32: =SUMIFS(Production_Log!$S$2:$S$5000,Production_Log!$C$2:$C$5000,$A32,Production_Log!$E$2:$E$5000,"L3")/SUMIFS(Production_Log!$J$2:$J$5000,Production_Log!$C$2:$C$5000,$A32,Production_Log!$E$2:$E$5000,"L3") -> 0.80419199 | E32: =SUMIFS(Production_Log!$S$2:$S$5000,Production_Log!$C$2:$C$5000,$A32,Production_Log!$E$2:$E$5000,"L4")/SUMIFS(Production_Log!$J$2:$J$5000,Production_Log!$C$2:$C$5000,$A32,Production_Log!$E$2:$E$5000,"L4") -> 0.68679505 | F32: =SUMIFS(Production_Log!$S$2:$S$5000,Production_Log!$C$2:$C$5000,$A32)/SUMIFS(Production_Log!$J$2:$J$5000,Production_Log!$C$2:$C$5000,$A32) -> 0.72108703 | G32: =SUMIFS(Production_Log!$L$2:$L$5000,Production_Log!$C$2:$C$5000,$A32)/SUMIFS(Production_Log!$J$2:$J$5000,Production_Log!$C$2:$C$5000,$A32) -> 0.85215686 | H32: =SUMIFS(Production_Log!$R$2:$R$5000,Production_Log!$C$2:$C$5000,$A32)/SUMIFS(Production_Log!$L$2:$L$5000,Production_Log!$C$2:$C$5000,$A32) -> 0.86450654 | I32: =SUMIFS(Production_Log!$S$2:$S$5000,Production_Log!$C$2:$C$5000,$A32)/SUMIFS(Production_Log!$R$2:$R$5000,Production_Log!$C$2:$C$5000,$A32) -> 0.97881328 | J32: =SUMIFS(Production_Log!$K$2:$K$5000,Production_Log!$C$2:$C$5000,$A32)/60 -> 289.03333
A33: 46082 | B33: =SUMIFS(Production_Log!$S$2:$S$5000,Production_Log!$C$2:$C$5000,$A33,Production_Log!$E$2:$E$5000,"L1")/SUMIFS(Production_Log!$J$2:$J$5000,Production_Log!$C$2:$C$5000,$A33,Production_Log!$E$2:$E$5000,"L1") -> 0.75605716 | C33: =SUMIFS(Production_Log!$S$2:$S$5000,Production_Log!$C$2:$C$5000,$A33,Production_Log!$E$2:$E$5000,"L2")/SUMIFS(Production_Log!$J$2:$J$5000,Production_Log!$C$2:$C$5000,$A33,Production_Log!$E$2:$E$5000,"L2") -> 0.66520438 | D33: =SUMIFS(Production_Log!$S$2:$S$5000,Production_Log!$C$2:$C$5000,$A33,Production_Log!$E$2:$E$5000,"L3")/SUMIFS(Production_Log!$J$2:$J$5000,Production_Log!$C$2:$C$5000,$A33,Production_Log!$E$2:$E$5000,"L3") -> 0.80019222 | E33: =SUMIFS(Production_Log!$S$2:$S$5000,Production_Log!$C$2:$C$5000,$A33,Production_Log!$E$2:$E$5000,"L4")/SUMIFS(Production_Log!$J$2:$J$5000,Production_Log!$C$2:$C$5000,$A33,Production_Log!$E$2:$E$5000,"L4") -> 0.6819693 | F33: =SUMIFS(Production_Log!$S$2:$S$5000,Production_Log!$C$2:$C$5000,$A33)/SUMIFS(Production_Log!$J$2:$J$5000,Production_Log!$C$2:$C$5000,$A33) -> 0.72095044 | G33: =SUMIFS(Production_Log!$L$2:$L$5000,Production_Log!$C$2:$C$5000,$A33)/SUMIFS(Production_Log!$J$2:$J$5000,Production_Log!$C$2:$C$5000,$A33) -> 0.85774511 | H33: =SUMIFS(Production_Log!$R$2:$R$5000,Production_Log!$C$2:$C$5000,$A33)/SUMIFS(Production_Log!$L$2:$L$5000,Production_Log!$C$2:$C$5000,$A33) -> 0.85933975 | I33: =SUMIFS(Production_Log!$S$2:$S$5000,Production_Log!$C$2:$C$5000,$A33)/SUMIFS(Production_Log!$R$2:$R$5000,Production_Log!$C$2:$C$5000,$A33) -> 0.97809775 | J33: =SUMIFS(Production_Log!$K$2:$K$5000,Production_Log!$C$2:$C$5000,$A33)/60 -> 280.63333
A34: 46113 | B34: =SUMIFS(Production_Log!$S$2:$S$5000,Production_Log!$C$2:$C$5000,$A34,Production_Log!$E$2:$E$5000,"L1")/SUMIFS(Production_Log!$J$2:$J$5000,Production_Log!$C$2:$C$5000,$A34,Production_Log!$E$2:$E$5000,"L1") -> 0.72895168 | C34: =SUMIFS(Production_Log!$S$2:$S$5000,Production_Log!$C$2:$C$5000,$A34,Production_Log!$E$2:$E$5000,"L2")/SUMIFS(Production_Log!$J$2:$J$5000,Production_Log!$C$2:$C$5000,$A34,Production_Log!$E$2:$E$5000,"L2") -> 0.54741815 | D34: =SUMIFS(Production_Log!$S$2:$S$5000,Production_Log!$C$2:$C$5000,$A34,Production_Log!$E$2:$E$5000,"L3")/SUMIFS(Production_Log!$J$2:$J$5000,Production_Log!$C$2:$C$5000,$A34,Production_Log!$E$2:$E$5000,"L3") -> 0.80063314 | E34: =SUMIFS(Production_Log!$S$2:$S$5000,Production_Log!$C$2:$C$5000,$A34,Production_Log!$E$2:$E$5000,"L4")/SUMIFS(Production_Log!$J$2:$J$5000,Production_Log!$C$2:$C$5000,$A34,Production_Log!$E$2:$E$5000,"L4") -> 0.69745865 | F34: =SUMIFS(Production_Log!$S$2:$S$5000,Production_Log!$C$2:$C$5000,$A34)/SUMIFS(Production_Log!$J$2:$J$5000,Production_Log!$C$2:$C$5000,$A34) -> 0.68380028 | G34: =SUMIFS(Production_Log!$L$2:$L$5000,Production_Log!$C$2:$C$5000,$A34)/SUMIFS(Production_Log!$J$2:$J$5000,Production_Log!$C$2:$C$5000,$A34) -> 0.81645634 | H34: =SUMIFS(Production_Log!$R$2:$R$5000,Production_Log!$C$2:$C$5000,$A34)/SUMIFS(Production_Log!$L$2:$L$5000,Production_Log!$C$2:$C$5000,$A34) -> 0.85588899 | I34: =SUMIFS(Production_Log!$S$2:$S$5000,Production_Log!$C$2:$C$5000,$A34)/SUMIFS(Production_Log!$R$2:$R$5000,Production_Log!$C$2:$C$5000,$A34) -> 0.97854063 | J34: =SUMIFS(Production_Log!$K$2:$K$5000,Production_Log!$C$2:$C$5000,$A34)/60 -> 389.06667
A35: 46143 | B35: =SUMIFS(Production_Log!$S$2:$S$5000,Production_Log!$C$2:$C$5000,$A35,Production_Log!$E$2:$E$5000,"L1")/SUMIFS(Production_Log!$J$2:$J$5000,Production_Log!$C$2:$C$5000,$A35,Production_Log!$E$2:$E$5000,"L1") -> 0.73206486 | C35: =SUMIFS(Production_Log!$S$2:$S$5000,Production_Log!$C$2:$C$5000,$A35,Production_Log!$E$2:$E$5000,"L2")/SUMIFS(Production_Log!$J$2:$J$5000,Production_Log!$C$2:$C$5000,$A35,Production_Log!$E$2:$E$5000,"L2") -> 0.65358436 | D35: =SUMIFS(Production_Log!$S$2:$S$5000,Production_Log!$C$2:$C$5000,$A35,Production_Log!$E$2:$E$5000,"L3")/SUMIFS(Production_Log!$J$2:$J$5000,Production_Log!$C$2:$C$5000,$A35,Production_Log!$E$2:$E$5000,"L3") -> 0.80110136 | E35: =SUMIFS(Production_Log!$S$2:$S$5000,Production_Log!$C$2:$C$5000,$A35,Production_Log!$E$2:$E$5000,"L4")/SUMIFS(Production_Log!$J$2:$J$5000,Production_Log!$C$2:$C$5000,$A35,Production_Log!$E$2:$E$5000,"L4") -> 0.67392164 | F35: =SUMIFS(Production_Log!$S$2:$S$5000,Production_Log!$C$2:$C$5000,$A35)/SUMIFS(Production_Log!$J$2:$J$5000,Production_Log!$C$2:$C$5000,$A35) -> 0.70727166 | G35: =SUMIFS(Production_Log!$L$2:$L$5000,Production_Log!$C$2:$C$5000,$A35)/SUMIFS(Production_Log!$J$2:$J$5000,Production_Log!$C$2:$C$5000,$A35) -> 0.84435708 | H35: =SUMIFS(Production_Log!$R$2:$R$5000,Production_Log!$C$2:$C$5000,$A35)/SUMIFS(Production_Log!$L$2:$L$5000,Production_Log!$C$2:$C$5000,$A35) -> 0.85788923 | I35: =SUMIFS(Production_Log!$S$2:$S$5000,Production_Log!$C$2:$C$5000,$A35)/SUMIFS(Production_Log!$R$2:$R$5000,Production_Log!$C$2:$C$5000,$A35) -> 0.97640251 | J35: =SUMIFS(Production_Log!$K$2:$K$5000,Production_Log!$C$2:$C$5000,$A35)/60 -> 316.73333
A36: 46174 | B36: =SUMIFS(Production_Log!$S$2:$S$5000,Production_Log!$C$2:$C$5000,$A36,Production_Log!$E$2:$E$5000,"L1")/SUMIFS(Production_Log!$J$2:$J$5000,Production_Log!$C$2:$C$5000,$A36,Production_Log!$E$2:$E$5000,"L1") -> 0.73715827 | C36: =SUMIFS(Production_Log!$S$2:$S$5000,Production_Log!$C$2:$C$5000,$A36,Production_Log!$E$2:$E$5000,"L2")/SUMIFS(Production_Log!$J$2:$J$5000,Production_Log!$C$2:$C$5000,$A36,Production_Log!$E$2:$E$5000,"L2") -> 0.66841632 | D36: =SUMIFS(Production_Log!$S$2:$S$5000,Production_Log!$C$2:$C$5000,$A36,Production_Log!$E$2:$E$5000,"L3")/SUMIFS(Production_Log!$J$2:$J$5000,Production_Log!$C$2:$C$5000,$A36,Production_Log!$E$2:$E$5000,"L3") -> 0.82671496 | E36: =SUMIFS(Production_Log!$S$2:$S$5000,Production_Log!$C$2:$C$5000,$A36,Production_Log!$E$2:$E$5000,"L4")/SUMIFS(Production_Log!$J$2:$J$5000,Production_Log!$C$2:$C$5000,$A36,Production_Log!$E$2:$E$5000,"L4") -> 0.68462823 | F36: =SUMIFS(Production_Log!$S$2:$S$5000,Production_Log!$C$2:$C$5000,$A36)/SUMIFS(Production_Log!$J$2:$J$5000,Production_Log!$C$2:$C$5000,$A36) -> 0.72032406 | G36: =SUMIFS(Production_Log!$L$2:$L$5000,Production_Log!$C$2:$C$5000,$A36)/SUMIFS(Production_Log!$J$2:$J$5000,Production_Log!$C$2:$C$5000,$A36) -> 0.85662542 | H36: =SUMIFS(Production_Log!$R$2:$R$5000,Production_Log!$C$2:$C$5000,$A36)/SUMIFS(Production_Log!$L$2:$L$5000,Production_Log!$C$2:$C$5000,$A36) -> 0.85979034 | I36: =SUMIFS(Production_Log!$S$2:$S$5000,Production_Log!$C$2:$C$5000,$A36)/SUMIFS(Production_Log!$R$2:$R$5000,Production_Log!$C$2:$C$5000,$A36) -> 0.9780125 | J36: =SUMIFS(Production_Log!$K$2:$K$5000,Production_Log!$C$2:$C$5000,$A36)/60 -> 304.13333

Sheet Downtime_Analysis
A1: Downtime & Bottleneck Analysis
A2: Pareto ranking is formula-driven (LARGE / INDEX-MATCH) so it re-sorts automatically when the log changes.
A3: 1. Downtime by reason (unsorted helper)
A4: Reason | B4: Events | C4: Hours | D4: Avg min / event | E4: Rank key (helper)
A5: Breakdown | B5: =COUNTIFS(Downtime_Log!$G$2:$G$20000,A5) -> 945 | C5: =SUMIFS(Downtime_Log!$I$2:$I$20000,Downtime_Log!$G$2:$G$20000,A5)/60 -> 658.66667 | D5: =IF(B5=0,0,C5*60/B5) -> 41.820106 | E5: =C5+ROW()/1000000 -> 658.66667
A6: Changeover | B6: =COUNTIFS(Downtime_Log!$G$2:$G$20000,A6) -> 148 | C6: =SUMIFS(Downtime_Log!$I$2:$I$20000,Downtime_Log!$G$2:$G$20000,A6)/60 -> 229.61667 | D6: =IF(B6=0,0,C6*60/B6) -> 93.087838 | E6: =C6+ROW()/1000000 -> 229.61667
A7: Material Shortage | B7: =COUNTIFS(Downtime_Log!$G$2:$G$20000,A7) -> 369 | C7: =SUMIFS(Downtime_Log!$I$2:$I$20000,Downtime_Log!$G$2:$G$20000,A7)/60 -> 238.66667 | D7: =IF(B7=0,0,C7*60/B7) -> 38.807588 | E7: =C7+ROW()/1000000 -> 238.66667
A8: QA/IPQC Hold | B8: =COUNTIFS(Downtime_Log!$G$2:$G$20000,A8) -> 298 | C8: =SUMIFS(Downtime_Log!$I$2:$I$20000,Downtime_Log!$G$2:$G$20000,A8)/60 -> 124.05 | D8: =IF(B8=0,0,C8*60/B8) -> 24.97651 | E8: =C8+ROW()/1000000 -> 124.05001
A9: Minor Stoppage | B9: =COUNTIFS(Downtime_Log!$G$2:$G$20000,A9) -> 7831 | C9: =SUMIFS(Downtime_Log!$I$2:$I$20000,Downtime_Log!$G$2:$G$20000,A9)/60 -> 559.63333 | D9: =IF(B9=0,0,C9*60/B9) -> 4.2878304 | E9: =C9+ROW()/1000000 -> 559.63334
A10: Utility Failure | B10: =COUNTIFS(Downtime_Log!$G$2:$G$20000,A10) -> 115 | C10: =SUMIFS(Downtime_Log!$I$2:$I$20000,Downtime_Log!$G$2:$G$20000,A10)/60 -> 67.766667 | D10: =IF(B10=0,0,C10*60/B10) -> 35.356522 | E10: =C10+ROW()/1000000 -> 67.766677
A13: 2. Pareto of downtime reasons (sorted)
A14: Rank | B14: Reason | C14: Hours | D14: % of total | E14: Cumulative % | F14: Priority
A15: 1 | B15: =INDEX($A$5:$A$10,MATCH(LARGE($E$5:$E$10,A15),$E$5:$E$10,0)) -> Breakdown | C15: =INDEX($C$5:$C$10,MATCH(LARGE($E$5:$E$10,A15),$E$5:$E$10,0)) -> 658.66667 | D15: =C15/SUM($C$5:$C$10) -> 0.35065304 | E15: =SUM($D$15:D15) -> 0.35065304 | F15: =IF(E15-D15<0.8,"Focus (vital few)","Later") -> Focus (vital few)
A16: 2 | B16: =INDEX($A$5:$A$10,MATCH(LARGE($E$5:$E$10,A16),$E$5:$E$10,0)) -> Minor Stoppage | C16: =INDEX($C$5:$C$10,MATCH(LARGE($E$5:$E$10,A16),$E$5:$E$10,0)) -> 559.63333 | D16: =C16/SUM($C$5:$C$10) -> 0.29793086 | E16: =SUM($D$15:D16) -> 0.6485839 | F16: =IF(E16-D16<0.8,"Focus (vital few)","Later") -> Focus (vital few)
A17: 3 | B17: =INDEX($A$5:$A$10,MATCH(LARGE($E$5:$E$10,A17),$E$5:$E$10,0)) -> Material Shortage | C17: =INDEX($C$5:$C$10,MATCH(LARGE($E$5:$E$10,A17),$E$5:$E$10,0)) -> 238.66667 | D17: =C17/SUM($C$5:$C$10) -> 0.12705849 | E17: =SUM($D$15:D17) -> 0.77564239 | F17: =IF(E17-D17<0.8,"Focus (vital few)","Later") -> Focus (vital few)
A18: 4 | B18: =INDEX($A$5:$A$10,MATCH(LARGE($E$5:$E$10,A18),$E$5:$E$10,0)) -> Changeover | C18: =INDEX($C$5:$C$10,MATCH(LARGE($E$5:$E$10,A18),$E$5:$E$10,0)) -> 229.61667 | D18: =C18/SUM($C$5:$C$10) -> 0.12224056 | E18: =SUM($D$15:D18) -> 0.89788295 | F18: =IF(E18-D18<0.8,"Focus (vital few)","Later") -> Focus (vital few)
A19: 5 | B19: =INDEX($A$5:$A$10,MATCH(LARGE($E$5:$E$10,A19),$E$5:$E$10,0)) -> QA/IPQC Hold | C19: =INDEX($C$5:$C$10,MATCH(LARGE($E$5:$E$10,A19),$E$5:$E$10,0)) -> 124.05 | D19: =C19/SUM($C$5:$C$10) -> 0.066040247 | E19: =SUM($D$15:D19) -> 0.9639232 | F19: =IF(E19-D19<0.8,"Focus (vital few)","Later") -> Later
A20: 6 | B20: =INDEX($A$5:$A$10,MATCH(LARGE($E$5:$E$10,A20),$E$5:$E$10,0)) -> Utility Failure | C20: =INDEX($C$5:$C$10,MATCH(LARGE($E$5:$E$10,A20),$E$5:$E$10,0)) -> 67.766667 | D20: =C20/SUM($C$5:$C$10) -> 0.036076803 | E20: =SUM($D$15:D20) -> 1 | F20: =IF(E20-D20<0.8,"Focus (vital few)","Later") -> Later
A24: 3. Downtime hours: Reason x Line
A25: Reason | B25: L1 | C25: L2 | D25: L3 | E25: L4 | F25: Total
A26: Breakdown | B26: =SUMIFS(Downtime_Log!$I$2:$I$20000,Downtime_Log!$G$2:$G$20000,$A26,Downtime_Log!$E$2:$E$20000,B$25)/60 -> 139.08333 | C26: =SUMIFS(Downtime_Log!$I$2:$I$20000,Downtime_Log!$G$2:$G$20000,$A26,Downtime_Log!$E$2:$E$20000,C$25)/60 -> 371.48333 | D26: =SUMIFS(Downtime_Log!$I$2:$I$20000,Downtime_Log!$G$2:$G$20000,$A26,Downtime_Log!$E$2:$E$20000,D$25)/60 -> 49.2 | E26: =SUMIFS(Downtime_Log!$I$2:$I$20000,Downtime_Log!$G$2:$G$20000,$A26,Downtime_Log!$E$2:$E$20000,E$25)/60 -> 98.9 | F26: =SUM(B26:E26) -> 658.66667
A27: Changeover | B27: =SUMIFS(Downtime_Log!$I$2:$I$20000,Downtime_Log!$G$2:$G$20000,$A27,Downtime_Log!$E$2:$E$20000,B$25)/60 -> 69.083333 | C27: =SUMIFS(Downtime_Log!$I$2:$I$20000,Downtime_Log!$G$2:$G$20000,$A27,Downtime_Log!$E$2:$E$20000,C$25)/60 -> 66.383333 | D27: =SUMIFS(Downtime_Log!$I$2:$I$20000,Downtime_Log!$G$2:$G$20000,$A27,Downtime_Log!$E$2:$E$20000,D$25)/60 -> 47.433333 | E27: =SUMIFS(Downtime_Log!$I$2:$I$20000,Downtime_Log!$G$2:$G$20000,$A27,Downtime_Log!$E$2:$E$20000,E$25)/60 -> 46.716667 | F27: =SUM(B27:E27) -> 229.61667
A28: Material Shortage | B28: =SUMIFS(Downtime_Log!$I$2:$I$20000,Downtime_Log!$G$2:$G$20000,$A28,Downtime_Log!$E$2:$E$20000,B$25)/60 -> 50.633333 | C28: =SUMIFS(Downtime_Log!$I$2:$I$20000,Downtime_Log!$G$2:$G$20000,$A28,Downtime_Log!$E$2:$E$20000,C$25)/60 -> 61.65 | D28: =SUMIFS(Downtime_Log!$I$2:$I$20000,Downtime_Log!$G$2:$G$20000,$A28,Downtime_Log!$E$2:$E$20000,D$25)/60 -> 26.966667 | E28: =SUMIFS(Downtime_Log!$I$2:$I$20000,Downtime_Log!$G$2:$G$20000,$A28,Downtime_Log!$E$2:$E$20000,E$25)/60 -> 99.416667 | F28: =SUM(B28:E28) -> 238.66667
A29: QA/IPQC Hold | B29: =SUMIFS(Downtime_Log!$I$2:$I$20000,Downtime_Log!$G$2:$G$20000,$A29,Downtime_Log!$E$2:$E$20000,B$25)/60 -> 46.766667 | C29: =SUMIFS(Downtime_Log!$I$2:$I$20000,Downtime_Log!$G$2:$G$20000,$A29,Downtime_Log!$E$2:$E$20000,C$25)/60 -> 46.5 | D29: =SUMIFS(Downtime_Log!$I$2:$I$20000,Downtime_Log!$G$2:$G$20000,$A29,Downtime_Log!$E$2:$E$20000,D$25)/60 -> 12.133333 | E29: =SUMIFS(Downtime_Log!$I$2:$I$20000,Downtime_Log!$G$2:$G$20000,$A29,Downtime_Log!$E$2:$E$20000,E$25)/60 -> 18.65 | F29: =SUM(B29:E29) -> 124.05
A30: Minor Stoppage | B30: =SUMIFS(Downtime_Log!$I$2:$I$20000,Downtime_Log!$G$2:$G$20000,$A30,Downtime_Log!$E$2:$E$20000,B$25)/60 -> 143.35 | C30: =SUMIFS(Downtime_Log!$I$2:$I$20000,Downtime_Log!$G$2:$G$20000,$A30,Downtime_Log!$E$2:$E$20000,C$25)/60 -> 153.58333 | D30: =SUMIFS(Downtime_Log!$I$2:$I$20000,Downtime_Log!$G$2:$G$20000,$A30,Downtime_Log!$E$2:$E$20000,D$25)/60 -> 59.933333 | E30: =SUMIFS(Downtime_Log!$I$2:$I$20000,Downtime_Log!$G$2:$G$20000,$A30,Downtime_Log!$E$2:$E$20000,E$25)/60 -> 202.76667 | F30: =SUM(B30:E30) -> 559.63333
A31: Utility Failure | B31: =SUMIFS(Downtime_Log!$I$2:$I$20000,Downtime_Log!$G$2:$G$20000,$A31,Downtime_Log!$E$2:$E$20000,B$25)/60 -> 20.9 | C31: =SUMIFS(Downtime_Log!$I$2:$I$20000,Downtime_Log!$G$2:$G$20000,$A31,Downtime_Log!$E$2:$E$20000,C$25)/60 -> 27.15 | D31: =SUMIFS(Downtime_Log!$I$2:$I$20000,Downtime_Log!$G$2:$G$20000,$A31,Downtime_Log!$E$2:$E$20000,D$25)/60 -> 11.383333 | E31: =SUMIFS(Downtime_Log!$I$2:$I$20000,Downtime_Log!$G$2:$G$20000,$A31,Downtime_Log!$E$2:$E$20000,E$25)/60 -> 8.3333333 | F31: =SUM(B31:E31) -> 67.766667
A32: Total | B32: =SUM(B26:B31) -> 469.81667 | C32: =SUM(C26:C31) -> 726.75 | D32: =SUM(D26:D31) -> 207.05 | E32: =SUM(E26:E31) -> 474.78333 | F32: =SUM(F26:F31) -> 1878.4
A35: 4. Downtime by machine (unsorted helper)
A36: Machine | B36: Line | C36: Total downtime (h) | D36: Breakdown (h) | E36: Events | F36: Rank key (helper)
A37: =Machine_Master!A2 -> Tablet Press 1 | B37: =Machine_Master!B2 -> L1 | C37: =SUMIFS(Downtime_Log!$I$2:$I$20000,Downtime_Log!$F$2:$F$20000,A37)/60 -> 278.75 | D37: =SUMIFS(Downtime_Log!$I$2:$I$20000,Downtime_Log!$F$2:$F$20000,A37,Downtime_Log!$G$2:$G$20000,"Breakdown")/60 -> 61.966667 | E37: =COUNTIFS(Downtime_Log!$F$2:$F$20000,A37) -> 1240 | F37: =C37+ROW()/1000000 -> 278.75004
A38: =Machine_Master!A3 -> Coating Pan 1 | B38: =Machine_Master!B3 -> L1 | C38: =SUMIFS(Downtime_Log!$I$2:$I$20000,Downtime_Log!$F$2:$F$20000,A38)/60 -> 150.65 | D38: =SUMIFS(Downtime_Log!$I$2:$I$20000,Downtime_Log!$F$2:$F$20000,A38,Downtime_Log!$G$2:$G$20000,"Breakdown")/60 -> 55.6 | E38: =COUNTIFS(Downtime_Log!$F$2:$F$20000,A38) -> 830 | F38: =C38+ROW()/1000000 -> 150.65004
A39: =Machine_Master!A4 -> Metal Detector 1 | B39: =Machine_Master!B4 -> L1 | C39: =SUMIFS(Downtime_Log!$I$2:$I$20000,Downtime_Log!$F$2:$F$20000,A39)/60 -> 40.416667 | D39: =SUMIFS(Downtime_Log!$I$2:$I$20000,Downtime_Log!$F$2:$F$20000,A39,Downtime_Log!$G$2:$G$20000,"Breakdown")/60 -> 21.516667 | E39: =COUNTIFS(Downtime_Log!$F$2:$F$20000,A39) -> 289 | F39: =C39+ROW()/1000000 -> 40.416706
A40: =Machine_Master!A5 -> Tablet Press 2 | B40: =Machine_Master!B5 -> L2 | C40: =SUMIFS(Downtime_Log!$I$2:$I$20000,Downtime_Log!$F$2:$F$20000,A40)/60 -> 493.18333 | D40: =SUMIFS(Downtime_Log!$I$2:$I$20000,Downtime_Log!$F$2:$F$20000,A40,Downtime_Log!$G$2:$G$20000,"Breakdown")/60 -> 252.18333 | E40: =COUNTIFS(Downtime_Log!$F$2:$F$20000,A40) -> 1572 | F40: =C40+ROW()/1000000 -> 493.18337
A41: =Machine_Master!A6 -> Coating Pan 2 | B41: =Machine_Master!B6 -> L2 | C41: =SUMIFS(Downtime_Log!$I$2:$I$20000,Downtime_Log!$F$2:$F$20000,A41)/60 -> 166.75 | D41: =SUMIFS(Downtime_Log!$I$2:$I$20000,Downtime_Log!$F$2:$F$20000,A41,Downtime_Log!$G$2:$G$20000,"Breakdown")/60 -> 76.616667 | E41: =COUNTIFS(Downtime_Log!$F$2:$F$20000,A41) -> 797 | F41: =C41+ROW()/1000000 -> 166.75004
A42: =Machine_Master!A7 -> Metal Detector 2 | B42: =Machine_Master!B7 -> L2 | C42: =SUMIFS(Downtime_Log!$I$2:$I$20000,Downtime_Log!$F$2:$F$20000,A42)/60 -> 66.816667 | D42: =SUMIFS(Downtime_Log!$I$2:$I$20000,Downtime_Log!$F$2:$F$20000,A42,Downtime_Log!$G$2:$G$20000,"Breakdown")/60 -> 42.683333 | E42: =COUNTIFS(Downtime_Log!$F$2:$F$20000,A42) -> 370 | F42: =C42+ROW()/1000000 -> 66.816709
A43: =Machine_Master!A8 -> Capsule Filler | B43: =Machine_Master!B8 -> L3 | C43: =SUMIFS(Downtime_Log!$I$2:$I$20000,Downtime_Log!$F$2:$F$20000,A43)/60 -> 152.58333 | D43: =SUMIFS(Downtime_Log!$I$2:$I$20000,Downtime_Log!$F$2:$F$20000,A43,Downtime_Log!$G$2:$G$20000,"Breakdown")/60 -> 29.75 | E43: =COUNTIFS(Downtime_Log!$F$2:$F$20000,A43) -> 638 | F43: =C43+ROW()/1000000 -> 152.58338
A44: =Machine_Master!A9 -> Capsule Polisher | B44: =Machine_Master!B9 -> L3 | C44: =SUMIFS(Downtime_Log!$I$2:$I$20000,Downtime_Log!$F$2:$F$20000,A44)/60 -> 54.466667 | D44: =SUMIFS(Downtime_Log!$I$2:$I$20000,Downtime_Log!$F$2:$F$20000,A44,Downtime_Log!$G$2:$G$20000,"Breakdown")/60 -> 19.45 | E44: =COUNTIFS(Downtime_Log!$F$2:$F$20000,A44) -> 374 | F44: =C44+ROW()/1000000 -> 54.466711
A45: =Machine_Master!A10 -> Blister Machine | B45: =Machine_Master!B10 -> L4 | C45: =SUMIFS(Downtime_Log!$I$2:$I$20000,Downtime_Log!$F$2:$F$20000,A45)/60 -> 315.6 | D45: =SUMIFS(Downtime_Log!$I$2:$I$20000,Downtime_Log!$F$2:$F$20000,A45,Downtime_Log!$G$2:$G$20000,"Breakdown")/60 -> 47.5 | E45: =COUNTIFS(Downtime_Log!$F$2:$F$20000,A45) -> 2074 | F45: =C45+ROW()/1000000 -> 315.60005
A46: =Machine_Master!A11 -> Cartoner | B46: =Machine_Master!B11 -> L4 | C46: =SUMIFS(Downtime_Log!$I$2:$I$20000,Downtime_Log!$F$2:$F$20000,A46)/60 -> 159.18333 | D46: =SUMIFS(Downtime_Log!$I$2:$I$20000,Downtime_Log!$F$2:$F$20000,A46,Downtime_Log!$G$2:$G$20000,"Breakdown")/60 -> 51.4 | E46: =COUNTIFS(Downtime_Log!$F$2:$F$20000,A46) -> 1522 | F46: =C46+ROW()/1000000 -> 159.18338
A50: 5. Machine ranking - bottleneck candidates (sorted)
...

Sheet Quality_Analysis
A1: Quality & Rejection Analysis
A2: Pareto uses production time lost to rejects (Rejected qty / ideal rate) so different units (tablets, capsules, strips) can be compared fairly.
A3: 1. Defects (unsorted helper)
A4: Defect type | B4: Process stage | C4: Rejected qty (own units) | D4: Production time lost (h) | E4: Rank key (helper)
A5: Weight variation | B5: Compression & Coating | C5: =SUMIFS(Quality_Log!$H$2:$H$20000,Quality_Log!$G$2:$G$20000,A5) -> 1226519 | D5: =SUMIFS(Quality_Log!$I$2:$I$20000,Quality_Log!$G$2:$G$20000,A5)/60 -> 22.863222 | E5: =D5+ROW()/1000000 -> 22.863227
A6: Capping / lamination | B6: Compression & Coating | C6: =SUMIFS(Quality_Log!$H$2:$H$20000,Quality_Log!$G$2:$G$20000,A6) -> 1115425 | D6: =SUMIFS(Quality_Log!$I$2:$I$20000,Quality_Log!$G$2:$G$20000,A6)/60 -> 20.801164 | E6: =D6+ROW()/1000000 -> 20.80117
A7: Coating defect | B7: Compression & Coating | C7: =SUMIFS(Quality_Log!$H$2:$H$20000,Quality_Log!$G$2:$G$20000,A7) -> 1540901 | D7: =SUMIFS(Quality_Log!$I$2:$I$20000,Quality_Log!$G$2:$G$20000,A7)/60 -> 30.068244 | E7: =D7+ROW()/1000000 -> 30.068251
A8: Chipping / broken tablet | B8: Compression & Coating | C8: =SUMIFS(Quality_Log!$H$2:$H$20000,Quality_Log!$G$2:$G$20000,A8) -> 892979 | D8: =SUMIFS(Quality_Log!$I$2:$I$20000,Quality_Log!$G$2:$G$20000,A8)/60 -> 16.647258 | E8: =D8+ROW()/1000000 -> 16.647266
A9: Hardness out of spec | B9: Compression & Coating | C9: =SUMIFS(Quality_Log!$H$2:$H$20000,Quality_Log!$G$2:$G$20000,A9) -> 558681 | D9: =SUMIFS(Quality_Log!$I$2:$I$20000,Quality_Log!$G$2:$G$20000,A9)/60 -> 10.41511 | E9: =D9+ROW()/1000000 -> 10.415119
A10: Sticking / picking | B10: Compression & Coating | C10: =SUMIFS(Quality_Log!$H$2:$H$20000,Quality_Log!$G$2:$G$20000,A10) -> 335406 | D10: =SUMIFS(Quality_Log!$I$2:$I$20000,Quality_Log!$G$2:$G$20000,A10)/60 -> 6.2530931 | E10: =D10+ROW()/1000000 -> 6.2531031
A11: Metal / foreign particle | B11: Compression & Coating | C11: =SUMIFS(Quality_Log!$H$2:$H$20000,Quality_Log!$G$2:$G$20000,A11) -> 222938 | D11: =SUMIFS(Quality_Log!$I$2:$I$20000,Quality_Log!$G$2:$G$20000,A11)/60 -> 4.1558835 | E11: =D11+ROW()/1000000 -> 4.1558945
A12: Fill-weight variation | B12: Capsule Filling | C12: =SUMIFS(Quality_Log!$H$2:$H$20000,Quality_Log!$G$2:$G$20000,A12) -> 338508 | D12: =SUMIFS(Quality_Log!$I$2:$I$20000,Quality_Log!$G$2:$G$20000,A12)/60 -> 10.420022 | E12: =D12+ROW()/1000000 -> 10.420034
A13: Locked / empty capsule | B13: Capsule Filling | C13: =SUMIFS(Quality_Log!$H$2:$H$20000,Quality_Log!$G$2:$G$20000,A13) -> 286560 | D13: =SUMIFS(Quality_Log!$I$2:$I$20000,Quality_Log!$G$2:$G$20000,A13)/60 -> 9.0022652 | E13: =D13+ROW()/1000000 -> 9.0022782
A14: Damaged / dented capsule | B14: Capsule Filling | C14: =SUMIFS(Quality_Log!$H$2:$H$20000,Quality_Log!$G$2:$G$20000,A14) -> 239292 | D14: =SUMIFS(Quality_Log!$I$2:$I$20000,Quality_Log!$G$2:$G$20000,A14)/60 -> 7.4748453 | E14: =D14+ROW()/1000000 -> 7.4748593
A15: Dust / contamination | B15: Capsule Filling | C15: =SUMIFS(Quality_Log!$H$2:$H$20000,Quality_Log!$G$2:$G$20000,A15) -> 96632 | D15: =SUMIFS(Quality_Log!$I$2:$I$20000,Quality_Log!$G$2:$G$20000,A15)/60 -> 2.9758422 | E15: =D15+ROW()/1000000 -> 2.9758572
A16: Telescoped capsule | B16: Capsule Filling | C16: =SUMIFS(Quality_Log!$H$2:$H$20000,Quality_Log!$G$2:$G$20000,A16) -> 77421 | D16: =SUMIFS(Quality_Log!$I$2:$I$20000,Quality_Log!$G$2:$G$20000,A16)/60 -> 2.3845701 | E16: =D16+ROW()/1000000 -> 2.3845861
... A21: Pinhole (leak test fail) | B21: Blister Packing | C21: =SUMIFS(Quality_Log!$H$2:$H$20000,Quality_Log!$G$2:$G$20000,A21) -> 54143 | D21: =SUMIFS(Quality_Log!$I$2:$I$20000,Quality_Log!$G$2:$G$20000,A21)/60 -> 4.0710063 | E21: =D21+ROW()/1000000 -> 4.0710273
A23: 2. Pareto of defects by production time lost (sorted)
A24: Rank | B24: Defect type | C24: Process stage | D24: Time lost (h) | E24: % of total | F24: Cumulative %
A25: 1 | B25: =INDEX($A$5:$A$21,MATCH(LARGE($E$5:$E$21,A25),$E$5:$E$21,0)) -> Coating defect | C25: =INDEX($B$5:$B$21,MATCH(LARGE($E$5:$E$21,A25),$E$5:$E$21,0)) -> Compression & Coating | D25: =INDEX($D$5:$D$21,MATCH(LARGE($E$5:$E$21,A25),$E$5:$E$21,0)) -> 30.068244 | E25: =D25/SUM($D$5:$D$21) -> 0.15243295 | F25: =SUM($E$25:E25) -> 0.15243295
A26: 2 | B26: =INDEX($A$5:$A$21,MATCH(LARGE($E$5:$E$21,A26),$E$5:$E$21,0)) -> Weight variation | C26: =INDEX($B$5:$B$21,MATCH(LARGE($E$5:$E$21,A26),$E$5:$E$21,0)) -> Compression & Coating | D26: =INDEX($D$5:$D$21,MATCH(LARGE($E$5:$E$21,A26),$E$5:$E$21,0)) -> 22.863222 | E26: =D26/SUM($D$5:$D$21) -> 0.11590662 | F26: =SUM($E$25:E26) -> 0.26833956
A27: 3 | B27: =INDEX($A$5:$A$21,MATCH(LARGE($E$5:$E$21,A27),$E$5:$E$21,0)) -> Capping / lamination | C27: =INDEX($B$5:$B$21,MATCH(LARGE($E$5:$E$21,A27),$E$5:$E$21,0)) -> Compression & Coating | D27: =INDEX($D$5:$D$21,MATCH(LARGE($E$5:$E$21,A27),$E$5:$E$21,0)) -> 20.801164 | E27: =D27/SUM($D$5:$D$21) -> 0.10545287 | F27: =SUM($E$25:E27) -> 0.37379243
A28: 4 | B28: =INDEX($A$5:$A$21,MATCH(LARGE($E$5:$E$21,A28),$E$5:$E$21,0)) -> Seal failure | C28: =INDEX($B$5:$B$21,MATCH(LARGE($E$5:$E$21,A28),$E$5:$E$21,0)) -> Blister Packing | D28: =INDEX($D$5:$D$21,MATCH(LARGE($E$5:$E$21,A28),$E$5:$E$21,0)) -> 18.984394 | E28: =D28/SUM($D$5:$D$21) -> 0.096242638 | F28: =SUM($E$25:E28) -> 0.47003507
A29: 5 | B29: =INDEX($A$5:$A$21,MATCH(LARGE($E$5:$E$21,A29),$E$5:$E$21,0)) -> Chipping / broken tablet | C29: =INDEX($B$5:$B$21,MATCH(LARGE($E$5:$E$21,A29),$E$5:$E$21,0)) -> Compression & Coating | D29: =INDEX($D$5:$D$21,MATCH(LARGE($E$5:$E$21,A29),$E$5:$E$21,0)) -> 16.647258 | E29: =D29/SUM($D$5:$D$21) -> 0.084394373 | F29: =SUM($E$25:E29) -> 0.55442945
A30: 6 | B30: =INDEX($A$5:$A$21,MATCH(LARGE($E$5:$E$21,A30),$E$5:$E$21,0)) -> Missing / broken tablet in pocket | C30: =INDEX($B$5:$B$21,MATCH(LARGE($E$5:$E$21,A30),$E$5:$E$21,0)) -> Blister Packing | D30: =INDEX($D$5:$D$21,MATCH(LARGE($E$5:$E$21,A30),$E$5:$E$21,0)) -> 12.833138 | E30: =D30/SUM($D$5:$D$21) -> 0.065058438 | F30: =SUM($E$25:E30) -> 0.61948788
A31: 7 | B31: =INDEX($A$5:$A$21,MATCH(LARGE($E$5:$E$21,A31),$E$5:$E$21,0)) -> Fill-weight variation | C31: =INDEX($B$5:$B$21,MATCH(LARGE($E$5:$E$21,A31),$E$5:$E$21,0)) -> Capsule Filling | D31: =INDEX($D$5:$D$21,MATCH(LARGE($E$5:$E$21,A31),$E$5:$E$21,0)) -> 10.420022 | E31: =D31/SUM($D$5:$D$21) -> 0.05282499 | F31: =SUM($E$25:E31) -> 0.67231287
A32: 8 | B32: =INDEX($A$5:$A$21,MATCH(LARGE($E$5:$E$21,A32),$E$5:$E$21,0)) -> Hardness out of spec | C32: =INDEX($B$5:$B$21,MATCH(LARGE($E$5:$E$21,A32),$E$5:$E$21,0)) -> Compression & Coating | D32: =INDEX($D$5:$D$21,MATCH(LARGE($E$5:$E$21,A32),$E$5:$E$21,0)) -> 10.41511 | E32: =D32/SUM($D$5:$D$21) -> 0.052800089 | F32: =SUM($E$25:E32) -> 0.72511296
A33: 9 | B33: =INDEX($A$5:$A$21,MATCH(LARGE($E$5:$E$21,A33),$E$5:$E$21,0)) -> Print / coding error | C33: =INDEX($B$5:$B$21,MATCH(LARGE($E$5:$E$21,A33),$E$5:$E$21,0)) -> Blister Packing | D33: =INDEX($D$5:$D$21,MATCH(LARGE($E$5:$E$21,A33),$E$5:$E$21,0)) -> 10.2244 | E33: =D33/SUM($D$5:$D$21) -> 0.051833272 | F33: =SUM($E$25:E33) -> 0.77694624
A34: 10 | B34: =INDEX($A$5:$A$21,MATCH(LARGE($E$5:$E$21,A34),$E$5:$E$21,0)) -> Locked / empty capsule | C34: =INDEX($B$5:$B$21,MATCH(LARGE($E$5:$E$21,A34),$E$5:$E$21,0)) -> Capsule Filling | D34: =INDEX($D$5:$D$21,MATCH(LARGE($E$5:$E$21,A34),$E$5:$E$21,0)) -> 9.0022652 | E34: =D34/SUM($D$5:$D$21) -> 0.045637577 | F34: =SUM($E$25:E34) -> 0.82258381
A35: 11 | B35: =INDEX($A$5:$A$21,MATCH(LARGE($E$5:$E$21,A35),$E$5:$E$21,0)) -> Foil wrinkle / misalignment | C35: =INDEX($B$5:$B$21,MATCH(LARGE($E$5:$E$21,A35),$E$5:$E$21,0)) -> Blister Packing | D35: =INDEX($D$5:$D$21,MATCH(LARGE($E$5:$E$21,A35),$E$5:$E$21,0)) -> 7.6810859 | E35: =D35/SUM($D$5:$D$21) -> 0.038939772 | F35: =SUM($E$25:E35) -> 0.86152359
A36: 12 | B36: =INDEX($A$5:$A$21,MATCH(LARGE($E$5:$E$21,A36),$E$5:$E$21,0)) -> Damaged / dented capsule | C36: =INDEX($B$5:$B$21,MATCH(LARGE($E$5:$E$21,A36),$E$5:$E$21,0)) -> Capsule Filling | D36: =INDEX($D$5:$D$21,MATCH(LARGE($E$5:$E$21,A36),$E$5:$E$21,0)) -> 7.4748453 | E36: =D36/SUM($D$5:$D$21) -> 0.037894222 | F36: =SUM($E$25:E36) -> 0.89941781
... A41: 17 | B41: =INDEX($A$5:$A$21,MATCH(LARGE($E$5:$E$21,A41),$E$5:$E$21,0)) -> Telescoped capsule | C41: =INDEX($B$5:$B$21,MATCH(LARGE($E$5:$E$21,A41),$E$5:$E$21,0)) -> Capsule Filling | D41: =INDEX($D$5:$D$21,MATCH(LARGE($E$5:$E$21,A41),$E$5:$E$21,0)) -> 2.3845701 | E41: =D41/SUM($D$5:$D$21) -> 0.012088735 | F41: =SUM($E$25:E41) -> 1
A43: 3. Rejection by line
A44: Line | B44: Total units | C44: Rejected units | D44: Rejection % | E44: Time lost to rejects (h)
A45: L1 | B45: =SUMIFS(Production_Log!$N$2:$N$5000,Production_Log!$E$2:$E$5000,A45) -> 145542398 | C45: =SUMIFS(Production_Log!$O$2:$O$5000,Production_Log!$E$2:$E$5000,A45) -> 2718730 | D45: =C45/B45 -> 0.018679986 | E45: =SUMIFS(Quality_Log!$I$2:$I$20000,Quality_Log!$D$2:$D$20000,A45)/60 -> 48.555372
A46: L2 | B46: =SUMIFS(Production_Log!$N$2:$N$5000,Production_Log!$E$2:$E$5000,A46) -> 113533889 | C46: =SUMIFS(Production_Log!$O$2:$O$5000,Production_Log!$E$2:$E$5000,A46) -> 3174119 | D46: =C46/B46 -> 0.027957459 | E46: =SUMIFS(Quality_Log!$I$2:$I$20000,Quality_Log!$D$2:$D$20000,A46)/60 -> 62.648603
A47: L3 | B47: =SUMIFS(Production_Log!$N$2:$N$5000,Production_Log!$E$2:$E$5000,A47) -> 60622920 | C47: =SUMIFS(Production_Log!$O$2:$O$5000,Production_Log!$E$2:$E$5000,A47) -> 1038413 | D47: =C47/B47 -> 0.01712905 | E47: =SUMIFS(Quality_Log!$I$2:$I$20000,Quality_Log!$D$2:$D$20000,A47)/60 -> 32.257545
A48: L4 | B48: =SUMIFS(Production_Log!$N$2:$N$5000,Production_Log!$E$2:$E$5000,A48) -> 31584578 | C48: =SUMIFS(Production_Log!$O$2:$O$5000,Production_Log!$E$2:$E$5000,A48) -> 714759 | D48: =C48/B48 -> 0.02263 | E48: =SUMIFS(Quality_Log!$I$2:$I$20000,Quality_Log!$D$2:$D$20000,A48)/60 -> 53.794024
A50: 4. Rejection by product
A51: Product | B51: Line | C51: Total units | D51: Rejected units | E51: Rejection % | F51: Time lost to rejects (h)
...

Sheet Scenario
A1: Improvement Scenario (What-if)
A2: Yellow cells are levers. This estimates POTENTIAL impact - it is a planning scenario, not a realised result.
A3: Improvement lever | B3: Reduction % | C3: Typical method
A4: Breakdown downtime reduction | B4: 0.3 | C4: Preventive / condition-based maintenance, spare-parts planning
A5: Changeover time reduction | B5: 0.25 | C5: SMED (quick changeover), standard changeover checklist
A6: Material-shortage downtime reduction | B6: 0.2 | C6: Line-side kitting, supplier delivery scheduling, safety stock
A7: Reject reduction | B7: 0.2 | C7: Process parameter control, in-process checks, root-cause (CAPA)
A10: Line | B10: Planned Prod. Time (h) | C10: Operating Time (h) | D10: Breakdown (h) | E10: Changeover (h) | F10: Material Shortage (h) | G10: Time recovered (h) | H10: Availability - current | I10: Availability - scenario | J10: Performance (held) | K10: Quality - current | L10: Quality - scenario | M10: OEE - current | N10: OEE - scenario | O10: OEE gain (pts) | P10: Extra good units / month (own units)
A11: L1 | B11: =OEE_Analysis!D5 -> 3378.25 | C11: =OEE_Analysis!E5 -> 2908.4333 | D11: =SUMIFS(Downtime_Log!$I$2:$I$20000,Downtime_Log!$E$2:$E$20000,$A11,Downtime_Log!$G$2:$G$20000,"Breakdown")/60 -> 139.08333 | E11: =SUMIFS(Downtime_Log!$I$2:$I$20000,Downtime_Log!$E$2:$E$20000,$A11,Downtime_Log!$G$2:$G$20000,"Changeover")/60 -> 69.083333 | F11: =SUMIFS(Downtime_Log!$I$2:$I$20000,Downtime_Log!$E$2:$E$20000,$A11,Downtime_Log!$G$2:$G$20000,"Material Shortage")/60 -> 50.633333 | G11: =D11*$B$4+E11*$B$5+F11*$B$6 -> 69.1225 | H11: =OEE_Analysis!G5 -> 0.86092898 | I11: =(C11+G11)/B11 -> 0.88139002 | J11: =OEE_Analysis!H5 -> 0.8815771 | K11: =OEE_Analysis!I5 -> 0.98106271 | L11: =1-(1-K11)*(1-$B$7) -> 0.98485017 | M11: =OEE_Analysis!J5 -> 0.74460234 | N11: =I11*J11*L11 -> 0.76524164 | O11: =N11-M11 -> 0.020639297 | P11: =(N11-M11)*B11*60*(SUMIFS(Production_Log!$P$2:$P$5000,Production_Log!$E$2:$E$5000,$A11)/SUMIFS(Production_Log!$S$2:$S$5000,Production_Log!$E$2:$E$5000,$A11))/Assumptions!$B$9 -> 659810.82
A12: L2 | B12: =OEE_Analysis!D6 -> 3313.25 | C12: =OEE_Analysis!E6 -> 2586.5 | D12: =SUMIFS(Downtime_Log!$I$2:$I$20000,Downtime_Log!$E$2:$E$20000,$A12,Downtime_Log!$G$2:$G$20000,"Breakdown")/60 -> 371.48333 | E12: =SUMIFS(Downtime_Log!$I$2:$I$20000,Downtime_Log!$E$2:$E$20000,$A12,Downtime_Log!$G$2:$G$20000,"Changeover")/60 -> 66.383333 | F12: =SUMIFS(Downtime_Log!$I$2:$I$20000,Downtime_Log!$E$2:$E$20000,$A12,Downtime_Log!$G$2:$G$20000,"Material Shortage")/60 -> 61.65 | G12: =D12*$B$4+E12*$B$5+F12*$B$6 -> 140.37083 | H12: =OEE_Analysis!G6 -> 0.78065344 | I12: =(C12+G12)/B12 -> 0.82301995 | J12: =OEE_Analysis!H6 -> 0.84539478 | K12: =OEE_Analysis!I6 -> 0.97134903 | L12: =1-(1-K12)*(1-$B$7) -> 0.97707922 | M12: =OEE_Analysis!J6 -> 0.64105184 | N12: =I12*J12*L12 -> 0.67982902 | O12: =N12-M12 -> 0.038777186 | P12: =(N12-M12)*B12*60*(SUMIFS(Production_Log!$P$2:$P$5000,Production_Log!$E$2:$E$5000,$A12)/SUMIFS(Production_Log!$S$2:$S$5000,Production_Log!$E$2:$E$5000,$A12))/Assumptions!$B$9 -> 1112609.3
A13: L3 | B13: =OEE_Analysis!D7 -> 2248 | C13: =OEE_Analysis!E7 -> 2040.95 | D13: =SUMIFS(Downtime_Log!$I$2:$I$20000,Downtime_Log!$E$2:$E$20000,$A13,Downtime_Log!$G$2:$G$20000,"Breakdown")/60 -> 49.2 | E13: =SUMIFS(Downtime_Log!$I$2:$I$20000,Downtime_Log!$E$2:$E$20000,$A13,Downtime_Log!$G$2:$G$20000,"Changeover")/60 -> 47.433333 | F13: =SUMIFS(Downtime_Log!$I$2:$I$20000,Downtime_Log!$E$2:$E$20000,$A13,Downtime_Log!$G$2:$G$20000,"Material Shortage")/60 -> 26.966667 | G13: =D13*$B$4+E13*$B$5+F13*$B$6 -> 32.011667 | H13: =OEE_Analysis!G7 -> 0.90789591 | I13: =(C13+G13)/B13 -> 0.92213597 | J13: =OEE_Analysis!H7 -> 0.90614108 | K13: =OEE_Analysis!I7 -> 0.98255773 | L13: =1-(1-K13)*(1-$B$7) -> 0.98604618 | M13: =OEE_Analysis!J7 -> 0.80833234 | N13: =I13*J13*L13 -> 0.82392568 | O13: =N13-M13 -> 0.015593343 | P13: =(N13-M13)*B13*60*(SUMIFS(Production_Log!$P$2:$P$5000,Production_Log!$E$2:$E$5000,$A13)/SUMIFS(Production_Log!$S$2:$S$5000,Production_Log!$E$2:$E$5000,$A13))/Assumptions!$B$9 -> 191571.71
A14: L4 | B14: =OEE_Analysis!D8 -> 3382 | C14: =OEE_Analysis!E8 -> 2907.2167 | D14: =SUMIFS(Downtime_Log!$I$2:$I$20000,Downtime_Log!$E$2:$E$20000,$A14,Downtime_Log!$G$2:$G$20000,"Breakdown")/60 -> 98.9 | E14: =SUMIFS(Downtime_Log!$I$2:$I$20000,Downtime_Log!$E$2:$E$20000,$A14,Downtime_Log!$G$2:$G$20000,"Changeover")/60 -> 46.716667 | F14: =SUMIFS(Downtime_Log!$I$2:$I$20000,Downtime_Log!$E$2:$E$20000,$A14,Downtime_Log!$G$2:$G$20000,"Material Shortage")/60 -> 99.416667 | G14: =D14*$B$4+E14*$B$5+F14*$B$6 -> 61.2325 | H14: =OEE_Analysis!G8 -> 0.85961463 | I14: =(C14+G14)/B14 -> 0.87772004 | J14: =OEE_Analysis!H8 -> 0.81541138 | K14: =OEE_Analysis!I8 -> 0.97730763 | L14: =1-(1-K14)*(1-$B$7) -> 0.9818461 | M14: =OEE_Analysis!J8 -> 0.68503357 | N14: =I14*J14*L14 -> 0.70271011 | O14: =N14-M14 -> 0.017676542 | P14: =(N14-M14)*B14*60*(SUMIFS(Production_Log!$P$2:$P$5000,Production_Log!$E$2:$E$5000,$A14)/SUMIFS(Production_Log!$S$2:$S$5000,Production_Log!$E$2:$E$5000,$A14))/Assumptions!$B$9 -> 132760.32
A15: Plant | B15: =SUM(B11:B14) -> 12321.5 | C15: =SUM(C11:C14) -> 10443.1 | D15: =SUM(D11:D14) -> 658.66667 | E15: =SUM(E11:E14) -> 229.61667 | F15: =SUM(F11:F14) -> 238.66667 | G15: =SUM(G11:G14) -> 302.7375 | H15: =C15/B15 -> 0.84755103 | I15: =(C15+G15)/B15 -> 0.87212089 | J15: =OEE_Analysis!H9 -> 0.85899666 | K15: =OEE_Analysis!I9 -> 0.97801086 | L15: ="n/a" -> n/a | M15: =OEE_Analysis!J9 -> 0.71203445 | N15: =SUMPRODUCT(N11:N14,B11:B14)/B15 -> 0.7358172 | O15: =N15-M15 -> 0.023782747 | P15: n/a (mixed units)
A17: Method: Availability scenario = (Operating time + recovered time) / Planned time. Performance is held at today's level (recovered time runs at the same speed). Quality scenario = 1 - (1 - current Quality) x (1 - reject reduction). Extra units = OEE gain x Planned time x effective ideal rate, per month.

Sheet Assumptions
A1: Assumptions & Parameters
A2: Blue = hard-coded input. Black = formula. Change inputs here; every analysis sheet recalculates.
A3: Parameter | B3: Value | C3: Note / basis
A4: Shift length (min) | B4: 480 | C4: 3 shifts x 8 h (A: 06-14, B: 14-22, C: 22-06)
A5: Calendar shifts per day per line | B5: 3 | C5: Used for Schedule Loading (24 h/day potential)
A6: Plan attainment factor (production target) | B6: 0.78 | C6: Target units = Planned Production Time x Ideal rate x factor (assumed planning norm)
A7: World-class OEE benchmark | B7: 0.85 | C7: Commonly cited benchmark (approx. 90% Avail x 95% Perf x 99.9% Quality)
A8: Plant working days in dataset | B8: =SUMPRODUCT((Production_Log!$B$2:$B$1664<>"")/COUNTIF(Production_Log!$B$2:$B$1664,Production_Log!$B$2:$B$1664&"")) -> 152 | C8: Distinct dates in Production_Log (Mon-Sat, minus holidays). Extend range if you add rows.
A9: Months in dataset | B9: 6 | C9: Jan-Jun 2026
A10: World-class Availability | B10: 0.9 | C10: Benchmark component
A11: World-class Performance | B11: 0.95 | C11: Benchmark component
A12: World-class Quality | B12: 0.999 | C12: Benchmark component
A15: Plant calendar assumptions (simulated)
A16: Production days: Monday-Saturday; Sundays off.
A17: Plant holidays assumed: 26-Jan, 04-Mar, 01-May.
A18: Line 2 annual preventive-maintenance shutdown: 10-12 Mar (no production rows).
A19: Line 3 (capsule filling) runs Shifts A and B only; other lines run A, B and C.
A20: Saturday Shift A carries +60 min planned preventive maintenance (excluded from Planned Production Time).
A21: Planned downtime baseline 30 min/shift (handover, meals, line clearance) - excluded from Planned Production Time.

Sheet Production_Log
A1: Run_ID | B1: Date | C1: Month | D1: Shift | E1: Line | F1: Product | G1: Batch_ID | H1: Shift_Time_min | I1: Planned_Downtime_min | J1: Planned_Production_Time_min | K1: Unplanned_Downtime_min | L1: Operating_Time_min | M1: Ideal_Rate_units_per_min | N1: Total_Units | O1: Rejected_Units | P1: Good_Units | Q1: Target_Units | R1: Ideal_Time_min | S1: Fully_Productive_Time_min | T1: Availability | U1: Performance | V1: Quality | W1: OEE | X1: Energy_kWh | Y1: Water_kL
